Workbook

Sheet Sheet1
A1: id | B1: name | C1: phone | D1: city | E1: created_at | F1: Name | H1: Status
A2: 5255c6c7-4089-4538-b7dc-2b093bc1798c | B2: A.K. HOSIERY STORE (Ambala) | C2: NULL | D2: Haryana | E2: 2026-01-10 15:46:44.071905+00 | F2: A.K. HOSIERY STORE (Ambala) | G2: 43
A3: 8bbd9eec-26e1-4cb1-bcf5-44f935144b19 | B3: Abhay Textiles (Delhi) | C3: NULL | D3: Delhi | E3: 2026-01-10 15:46:44.071905+00 | F3: Abhay Textiles (Delhi) | G3: 25
A4: aacc0444-2a77-40e7-a894-927637cb64ba | B4: ABHISHEK HOSIERY & GENERAL STORE (Pirawa) | C4: NULL | D4: Rajasthan | E4: 2026-01-10 15:46:44.071905+00 | F4: ABHISHEK HOSIERY & GENERAL STORE (Pirawa) | G4: 26
A5: 211cea54-caed-4eb0-8fec-99e573c3a7f2 | B5: ABNASHI DASS HANS RAJ (AMBALA CITY) | C5: NULL | D5: Haryana | E5: 2026-01-10 15:46:44.071905+00 | F5: ABNASHI DASS HANS RAJ (AMBALA CITY) | G5: 27
A6: 6cd58a92-8c88-4975-b16a-64d9865569f1 | B6: Acron Incorporation | C6: NULL | D6: Delhi | E6: 2026-01-10 15:46:44.071905+00 | F6: Acron Incorporation | G6: 28
A7: dcf4edc5-fcec-4919-b8db-9ea9ed77ce93 | B7: Adarsh Agency (Dholpur) | C7: NULL | D7: Rajasthan | E7: 2026-01-10 15:46:44.071905+00 | F7: Adarsh Agency (Dholpur) | G7: 29
A8: 153aaf83-86ea-4755-aa50-84d58a9ad903 | B8: Adarsh Hosiery (Karnal) | C8: NULL | D8: Haryana | E8: 2026-01-10 15:46:44.071905+00 | F8: Adarsh Hosiery (Karnal) | G8: 30
A9: 7e883730-febb-43a0-a6c5-757d4c74f288 | B9: AGARWAL HOSIERY(MEERUT) | C9: NULL | D9: Uttar Pradesh | E9: 2026-01-10 15:46:44.071905+00 | F9: AGARWAL HOSIERY(MEERUT) | G9: 31
A10: ccba84d5-d7f6-45c6-83bc-06e5ef7e7abe | B10: AGGARWAL AGENCIES | C10: NULL | D10: Delhi | E10: 2026-01-10 15:46:44.071905+00 | F10: AGGARWAL AGENCIES | G10: 32
A11: b994a42f-12d6-4bdd-88ba-52e638ace543 | B11: AGGARWAL DRESSES GN | C11: NULL | D11: Delhi | E11: 2026-01-10 15:46:44.071905+00 | F11: AGGARWAL DRESSES GN | G11: 33
A12: 9b5d3c95-86ab-4fbe-8d76-34728ee8bbbc | B12: AGGARWAL HOSIERY (Avantika, Delhi) | C12: NULL | D12: Delhi | E12: 2026-01-10 15:46:44.071905+00 | F12: AGGARWAL HOSIERY (Avantika, Delhi) | G12: 34
A13: d9513a88-ae74-4777-9c8a-4b7991cb8006 | B13: AGGARWAL HOSIERY CENTRE | C13: NULL | D13: Delhi | E13: 2026-01-10 15:46:44.071905+00 | F13: AGGARWAL HOSIERY CENTRE | G13: 35
... A48: 6819705a-274a-4e21-8a49-250c2ad02baa | B48: ARORA GENERAL STORE (Jalandhar) | C48: NULL | D48: Punjab | E48: 2026-01-10 15:46:44.071905+00 | F48: ARORA GENERAL STORE (Jalandhar) | G48: 71
A49: a67d81a0-9e29-4e7b-a8cb-2673cf28a89b | B49: Arora Hosiery | C49: 9250170777 | D49: Moti Nagar (Delhi) | E49: 2025-12-28 14:02:32.476972+00 | F49: ARORA HOSIERY | G49: 747
A50: 8a2bb72c-43b9-4210-9e94-d26336c9db19 | B50: ARORA HOSIERY (BAREILLY) | C50: NULL | D50: Uttar Pradesh | E50: 2026-01-10 15:46:44.071905+00 | F50: ARORA HOSIERY (BAREILLY) | G50: 72
A51: bb178397-1ae3-49a3-b575-8a51cd613dc1 | B51: Arora Hosiery (Moti Nagar) | C51: NULL | D51: Delhi | E51: 2026-01-10 15:46:44.071905+00 | F51: Arora Hosiery (Moti Nagar) | G51: 699
A52: 15bef1cc-837c-478e-bbb2-d974741b66c6 | B52: ARORA HOSIERY (Panipat) | C52: NULL | D52: Haryana | E52: 2026-01-10 15:46:44.071905+00 | F52: ARORA HOSIERY (Panipat) | G52: 73
A53: f560839d-025b-4e20-b969-13ebff220a5a | B53: ARVIND GARMENTS (Baraut) | C53: NULL | D53: Uttar Pradesh | E53: 2026-01-10 15:46:44.071905+00 | F53: ARVIND GARMENTS (Baraut) | G53: 74
A54: 6496b8de-ed88-490b-8479-ce5e02d056d4 | B54: ASHOK KUMAR RAMESH KUMAR (Sirohi) | C54: NULL | D54: Rajasthan | E54: 2026-01-10 15:46:44.071905+00 | F54: ASHOK KUMAR RAMESH KUMAR (Sirohi) | G54: 76
A55: 1c1f2be2-5292-4404-8760-33e454992ec4 | B55: ASHOK TRADERS (Farrukhabad) | C55: NULL | D55: Uttar Pradesh | E55: 2026-01-10 15:46:44.071905+00 | F55: ASHOK TRADERS (Farrukhabad) | G55: 77
A56: aa3471b4-dc7c-4b7c-935a-f4093b56bd51 | B56: ASHOKA BANGLE STORE (Bhatinda) | C56: NULL | D56: Punjab | E56: 2026-01-10 15:46:44.071905+00 | F56: ASHOKA BANGLE STORE (Bhatinda) | G56: 75
A57: 0a9f6720-cfa1-4e43-9261-ca16c60dac65 | B57: ASHU HOSIERY (Fatehabad) | C57: NULL | D57: Haryana | E57: 2026-01-10 15:46:44.071905+00 | F57: ASHU HOSIERY (Fatehabad) | G57: 78
A58: e4994e06-1d14-4692-83b4-883f4f293962 | B58: ASIAN HOSIERY | C58: NULL | D58: Delhi | E58: 2026-01-10 15:46:44.071905+00 | F58: ASIAN HOSIERY | G58: 79
A59: 2e3e6866-562d-4baa-84fc-fb16936f954b | B59: ASIJA GENERAL STORE (Hisar) | C59: NULL | D59: Haryana | E59: 2026-01-10 15:46:44.071905+00 | F59: ASIJA GENERAL STORE (Hisar) | G59: 80
A60: 72eb05a6-238c-4846-8b6b-a4ff781b2164 | B60: ASLAM HOSIERY | C60: NULL | D60: Delhi | E60: 2026-01-10 15:46:44.071905+00 | F60: ASLAM HOSIERY | G60: 81
A61: a690b092-4f06-4a91-bcf0-d2b2e2ffa347 | B61: ASPAK AHMED (Bisalpur) | C61: NULL | D61: Uttar Pradesh | E61: 2026-01-10 15:46:44.071905+00 | F61: ASPAK AHMED (Bisalpur) | G61: 82
... A192: 7934d111-09d3-463a-914b-5aa1a1b930f8 | B192: GOSWAMI GARMENTS (Bhawani Mandi) | C192: NULL | D192: Rajasthan | E192: 2026-01-10 15:46:44.071905+00 | F192: GOSWAMI GARMENTS (Bhawani Mandi) | G192: 204
A193: c44d163b-035e-4a51-9cd2-c3bd89308188 | B193: GOURAV BOOK STORE (C/O MOHAN SINGH BANDHAN)(D) | C193: NULL | D193: Delhi | E193: 2026-01-10 15:46:44.071905+00 | F193: NULL | G193: 205 | H193: Upd
A194: 398983a4-1cd5-4800-8eaf-cc2fc44b1417 | B194: GOYAL & SONS CLOTH HOUSE | C194: NULL | D194: Delhi | E194: 2026-01-10 15:46:44.071905+00 | F194: GOYAL & SONS CLOTH HOUSE | G194: 207
A195: 1d2f294a-d485-47ae-abb3-1ad951c2fbe5 | B195: Goyal Garments (Sonia Vihar) (D) | C195: NULL | D195: Delhi | E195: 2026-01-10 15:46:44.071905+00 | F195: Goyal Garments (Sonia Vihar) (D) | G195: 726
A196: 147a997c-706c-47a8-b7cd-39668bc7c975 | B196: Goyal Garments Hissar | C196: NULL | D196: Haryana | E196: 2026-01-10 15:46:44.071905+00 | F196: NULL | G196: NULL | H196: AM
A197: aeb4b79e-ee72-4a62-adde-e898587ba01b | B197: GOYAL HOSIERY (Bareilly) | C197: NULL | D197: Uttar Pradesh | E197: 2026-01-10 15:46:44.071905+00 | F197: GOYAL HOSIERY (Bareilly) | G197: 206
A198: 3569a3b1-04bb-42e4-adc5-9325f400e3a4 | B198: GOYAL HOSIERY (DELHI) | C198: NULL | D198: Delhi | E198: 2026-01-10 15:46:44.071905+00 | F198: NULL | G198: NULL | H198: AM
A199: c0e9b0ff-aed0-4e98-8e3c-0fc1d2dfb0cf | B199: GOYAL TRADERS (Dhampur) | C199: NULL | D199: Uttar Pradesh | E199: 2026-01-10 15:46:44.071905+00 | F199: GOYAL TRADERS (Dhampur) | G199: 208
A200: 7bca2061-1e47-469c-8507-40f114ae27d6 | B200: GULATI HOSIERY | C200: NULL | D200: Delhi | E200: 2026-01-10 15:46:44.071905+00 | F200: GULATI HOSIERY | G200: 209
A201: f0e86222-03c7-41ca-87c1-5abfcfa3684e | B201: GULSHAN SALES (Baran) | C201: NULL | D201: Rajasthan | E201: 2026-01-10 15:46:44.071905+00 | F201: GULSHAN SALES (Baran) | G201: 210
A202: 7a66c18b-b45f-482d-a2a4-f25c5f2377e5 | B202: GULZARI LAL & SONS | C202: NULL | D202: Delhi | E202: 2026-01-10 15:46:44.071905+00 | F202: GULZARI LAL & SONS | G202: 211
A203: 52b6398f-5e7a-44ee-bdd9-5d5a0da46613 | B203: GUPTA G TRADING (D) | C203: NULL | D203: Delhi | E203: 2026-01-10 15:46:44.071905+00 | F203: GUPTA G TRADING (D) | G203: 217
A204: f4a01e85-b6b7-4cdf-b036-4b4b08ade2c1 | B204: GUPTA & SONS | C204: NULL | D204: Delhi | E204: 2026-01-10 15:46:44.071905+00 | F204: GUPTA & SONS | G204: 218
...

Sheet MaterialProduct
A1: id | B1: base_name | C1: category | D1: created_at | E1: base_name_nick | F1: BoxMultiple | G1: Xlookup
A2: b0fa95b8-a1ac-4d00-8881-60ae7663805d | B2: DIVYA SUPER Fine White RNS | D2: 2026-01-10 16:24:33.294862+00 | E2: Super W RNS | F2: 1 | G2: =VLOOKUP(TRIM(B2),SGMProductSpl!$A$1:$C$170,3,FALSE) -> #N/A
A3: ca648c96-7b97-4a2d-8313-025d34664d76 | B3: DIVYA SUPER Fine White RN | D3: 2026-01-10 16:24:33.294862+00 | E3: Super W RN | F3: 1 | G3: =VLOOKUP(TRIM(B3),SGMProductSpl!$A$1:$C$170,3,FALSE) -> #N/A
A4: 04fc4dec-b1fa-4020-95c1-ba152dbf6260 | B4: MAESTRO Casuals SHORTS N-1 | D4: 2026-01-10 16:24:33.294862+00 | E4: Shorts N-1 Piping | F4: 1 | G4: =VLOOKUP(TRIM(B4),SGMProductSpl!$A$1:$C$170,3,FALSE) -> 5
A5: 1e6cba55-d383-4ce6-82d2-a809ee3b1bfe | B5: MAESTRO Casuals SHORTS D-11 | D5: 2026-01-10 16:24:33.294862+00 | E5: Shorts D-11 Plain | F5: 1 | G5: =VLOOKUP(TRIM(B5),SGMProductSpl!$A$1:$C$170,3,FALSE) -> 5
A6: 77dab30b-4aec-40f4-9e05-03326d055250 | B6: MAESTRO PLATINUM ROMANCE O/E 2 PC | D6: 2026-01-10 16:24:33.294862+00 | E6: Plat. ROMANCE | F6: 1 | G6: =VLOOKUP(TRIM(B6),SGMProductSpl!$A$1:$C$170,3,FALSE) -> #N/A
A7: c9b493af-af6b-4596-a31d-64ad5b142bda | B7: MAESTRO PLATINUM MINI OE 2 PC | D7: 2026-01-10 16:24:33.294862+00 | E7: Plat. MINI | F7: 1 | G7: =VLOOKUP(TRIM(B7),SGMProductSpl!$A$1:$C$170,3,FALSE) -> #N/A
A8: 943ca12e-6773-4cd5-a867-0503f58c30b0 | B8: MAESTRO Platinum Longs OE (2 Pc) | D8: 2026-01-10 16:24:33.294862+00 | E8: Plat. Longs | F8: 1 | G8: =VLOOKUP(TRIM(B8),SGMProductSpl!$A$1:$C$170,3,FALSE) -> #N/A
A9: bd38f77e-7109-4d5c-9d9b-7fcf7e7db074 | B9: MAESTRO PLATINUM ICD 2 PC | D9: 2026-01-10 16:24:33.294862+00 | E9: Plat. ICD | F9: 1 | G9: =VLOOKUP(TRIM(B9),SGMProductSpl!$A$1:$C$170,3,FALSE) -> #N/A
A10: cb07e6da-f934-49f5-b903-9e1ee05d8ee7 | B10: MAESTRO PLATINUM FINE 2 Pc RNS | D10: 2026-01-10 16:24:33.294862+00 | E10: Plat. FINE RNS | F10: 1 | G10: =VLOOKUP(TRIM(B10),SGMProductSpl!$A$1:$C$170,3,FALSE) -> #N/A
A11: 9684649f-f6a7-4ebb-b3ed-18e47985725e | B11: MAESTRO PLATINUM FINE 2 Pc RN | D11: 2026-01-10 16:24:33.294862+00 | E11: Plat. FINE RN | F11: 1 | G11: =VLOOKUP(TRIM(B11),SGMProductSpl!$A$1:$C$170,3,FALSE) -> #N/A
A12: d10a9e85-e3c2-42eb-92a8-98bd94b5b5d8 | B12: DIVYA Nice GYM VEST Plain | D12: 2026-01-10 16:24:33.294862+00 | E12: Nice GYM | F12: 1 | G12: =VLOOKUP(TRIM(B12),SGMProductSpl!$A$1:$C$170,3,FALSE) -> #N/A
A13: 97d05a2b-2a1a-4d9c-ac21-1c0a35a4d174 | B13: MAESTRO NICE PRINT BLOOMER | D13: 2026-01-10 16:24:33.294862+00 | E13: Nice Bloomer PRINT | F13: 1 | G13: =VLOOKUP(TRIM(B13),SGMProductSpl!$A$1:$C$170,3,FALSE) -> #N/A
... A49: d817caea-9348-46df-8c55-7bd37e73f6a4 | B49: Divya MAESTRO CATCH 2 PCS RN | D49: 2026-01-10 16:24:33.294862+00 | E49: Catch RN | F49: 1 | G49: =VLOOKUP(TRIM(B49),SGMProductSpl!$A$1:$C$170,3,FALSE) -> #N/A
A50: 1fbb67ba-d1df-4004-be8c-3acd68bc134e | B50: AUDI Kids Derbi 4pcs Set | D50: 2026-01-10 16:24:33.294862+00 | F50: 1 | G50: =VLOOKUP(TRIM(B50),SGMProductSpl!$A$1:$C$170,3,FALSE) -> #N/A
A51: 8b958731-d0d6-41a6-87e2-d23332bb8e2a | B51: AUDI Kids Derbi 6pcs Set | D51: 2026-01-10 16:24:33.294862+00 | F51: 1 | G51: =VLOOKUP(TRIM(B51),SGMProductSpl!$A$1:$C$170,3,FALSE) -> #N/A
A52: 10fd5477-743a-413d-9ccb-8cdf7653de77 | B52: AUDI OSWAL DARK Lower OE | D52: 2026-01-10 16:24:33.294862+00 | F52: 1 | G52: =VLOOKUP(TRIM(B52),SGMProductSpl!$A$1:$C$170,3,FALSE) -> #N/A
A53: eb73680e-3e02-4b56-8939-2d40541960f6 | B53: AUDI OSWAL DARK RN | D53: 2026-01-10 16:24:33.294862+00 | F53: 1 | G53: =VLOOKUP(TRIM(B53),SGMProductSpl!$A$1:$C$170,3,FALSE) -> #N/A
A54: 5727561f-fb23-4282-8e55-515ce58b4a88 | B54: AUDI OSWAL Light Lower OE | D54: 2026-01-10 16:24:33.294862+00 | F54: 1 | G54: =VLOOKUP(TRIM(B54),SGMProductSpl!$A$1:$C$170,3,FALSE) -> #N/A
A55: b324f87b-9062-44a0-aab2-8042bfa75563 | B55: AUDI OSWAL Light RN | D55: 2026-01-10 16:24:33.294862+00 | F55: 1 | G55: =VLOOKUP(TRIM(B55),SGMProductSpl!$A$1:$C$170,3,FALSE) -> #N/A
A56: efde0389-5475-4d90-ad50-2e04d9ab723b | B56: AUDI OSWAL Light VN | D56: 2026-01-10 16:24:33.294862+00 | F56: 1 | G56: =VLOOKUP(TRIM(B56),SGMProductSpl!$A$1:$C$170,3,FALSE) -> #N/A
A57: 48ab7090-8923-4775-a31a-9e92070490be | B57: AUDI Warming LightGrey Lower | D57: 2026-01-10 16:24:33.294862+00 | F57: 1 | G57: =VLOOKUP(TRIM(B57),SGMProductSpl!$A$1:$C$170,3,FALSE) -> #N/A
A58: e001a8d4-ac19-4927-a0e6-6e631f94b55a | B58: AUDI Warming LightGrey RN | D58: 2026-01-10 16:24:33.294862+00 | F58: 1 | G58: =VLOOKUP(TRIM(B58),SGMProductSpl!$A$1:$C$170,3,FALSE) -> #N/A
A59: 4256c3c3-5a93-4a1d-8ad5-967525706f69 | B59: BD OSWAL LOWER | D59: 2026-01-10 16:24:33.294862+00 | F59: 1 | G59: =VLOOKUP(TRIM(B59),SGMProductSpl!$A$1:$C$170,3,FALSE) -> #N/A
A60: 8007f6f9-6d75-4c00-987b-a2c8d36dd4a9 | B60: BD OSWAL RN | D60: 2026-01-10 16:24:33.294862+00 | F60: 1 | G60: =VLOOKUP(TRIM(B60),SGMProductSpl!$A$1:$C$170,3,FALSE) -> #N/A
A61: a2f98337-b587-4b3d-857f-36316818e566 | B61: BD OSWAL VN | D61: 2026-01-10 16:24:33.294862+00 | F61: 1 | G61: =VLOOKUP(TRIM(B61),SGMProductSpl!$A$1:$C$170,3,FALSE) -> #N/A
A62: 6d9c096a-84b3-490c-8e17-7cf2c0baf7e7 | B62: BED SHEET 1+2 | D62: 2026-01-10 16:24:33.294862+00 | F62: 1 | G62: 1
A63: 80b104e3-f0cc-49ac-a49d-5b59873953fd | B63: Bedsheet Double Bed | D63: 2026-01-10 16:24:33.294862+00 | F63: 1 | G63: =VLOOKUP(TRIM(B63),SGMProductSpl!$A$1:$C$170,3,FALSE) -> #N/A
A64: 21ea9f73-fbaa-434a-a43f-7a4a3be5f9fb | B64: BodyGuard FLAIR Gents SET RNFS+I/E | D64: 2026-01-10 16:24:33.294862+00 | F64: 1 | G64: =VLOOKUP(TRIM(B64),SGMProductSpl!$A$1:$C$170,3,FALSE) -> 1
A65: 65fc7fe1-14f0-4291-93ea-8a84f5ec85a4 | B65: BodyGuard FLAIR Kids SET RNFS+I/E | D65: 2026-01-10 16:24:33.294862+00 | F65: 1 | G65: =VLOOKUP(TRIM(B65),SGMProductSpl!$A$1:$C$170,3,FALSE) -> 1
A66: cc505735-898e-4ad8-8d77-37d997038605 | B66: BodyGuard FLAIR Ladies SET RNFS 3/4+I/E | D66: 2026-01-10 16:24:33.294862+00 | F66: 1 | G66: =VLOOKUP(TRIM(B66),SGMProductSpl!$A$1:$C$170,3,FALSE) -> 1
A67: b4040a8b-227c-4a0b-8158-22853d441e27 | B67: BOYS MEGHA C/S TSHIRT RN | D67: 2026-01-10 16:24:33.294862+00 | F67: 1 | G67: =VLOOKUP(TRIM(B67),SGMProductSpl!$A$1:$C$170,3,FALSE) -> #N/A
A68: ceb825d5-d3b2-4b74-919c-e75006fce8ba | B68: COMMANDER OSWAL RN | D68: 2026-01-10 16:24:33.294862+00 | F68: 1 | G68: =VLOOKUP(TRIM(B68),SGMProductSpl!$A$1:$C$170,3,FALSE) -> 3
A69: 82358935-e086-4a42-8969-af1642a66641 | B69: COMMANDER OSWAL TSR | D69: 2026-01-10 16:24:33.294862+00 | F69: 1 | G69: =VLOOKUP(TRIM(B69),SGMProductSpl!$A$1:$C$170,3,FALSE) -> 3
A70: 03ae5e3b-4df4-4ab9-874d-58c3c4ed85d6 | B70: COMMANDER OSWAL VN | D70: 2026-01-10 16:24:33.294862+00 | F70: 1 | G70: =VLOOKUP(TRIM(B70),SGMProductSpl!$A$1:$C$170,3,FALSE) -> 3
A71: 21167262-7a48-4afa-8d27-363ed967ffd8 | B71: DIVYA ALIA PANTY (1 PC) PLAIN | D71: 2026-01-10 16:24:33.294862+00 | F71: 1 | G71: =VLOOKUP(TRIM(B71),SGMProductSpl!$A$1:$C$170,3,FALSE) -> #N/A
A72: 096275fd-6336-4168-8b6b-7f190327cdba | B72: DIVYA ALIA PANTY (1 PC) PRINT | D72: 2026-01-10 16:24:33.294862+00 | F72: 1 | G72: =VLOOKUP(TRIM(B72),SGMProductSpl!$A$1:$C$170,3,FALSE) -> #N/A
A73: 72675cff-96cb-4aa7-9b7a-9e90d56005e2 | B73: DIVYA COMM Color T/S RN TS | D73: 2026-01-10 16:24:33.294862+00 | F73: 1 | G73: =VLOOKUP(TRIM(B73),SGMProductSpl!$A$1:$C$170,3,FALSE) -> #N/A
A74: 3e03fccb-5087-485b-acd1-69b953daa634 | B74: DIVYA COMM WHITE T/S RN TS | D74: 2026-01-10 16:24:33.294862+00 | F74: 1 | G74: =VLOOKUP(TRIM(B74),SGMProductSpl!$A$1:$C$170,3,FALSE) -> #N/A
... A284: 1b79ce57-401e-4b79-b849-dbbf65065240 | B284: Viray Oswal Thermal RN | D284: 2026-01-10 16:24:33.294862+00 | F284: 1 | G284: =VLOOKUP(TRIM(B284),SGMProductSpl!$A$1:$C$170,3,FALSE) -> #N/A

Sheet SGMProductSpl
A1: Product | B1: Unit | C1: Multiple
A2: BD Oswal Lower | B2: 35 | C2: 3
A3: BD Oswal RN | B3: 35 | C3: 3
A4: BD Oswal VN | B4: 35 | C4: 3
A5: Bed Sheet 1+2 | B5: 35
A6: Blanket (Oshil Vav Supersoft | B6: 35
A7: BodyGuard FLAIR Gents SET RNFS+I/E | B7: 58 | C7: 1
A8: BodyGuard FLAIR Kids SET RNFS+I/E | B8: 58 | C8: 1
A9: BodyGuard FLAIR Ladies SET RNFS 3/4+I/E | B9: 58 | C9: 1
A10: COMFORTER 500 | B10: 35
A11: Comforter WINTER | B11: 35
A12: Commander Oswal RN | B12: 35 | C12: 3
A13: Commander Oswal Tsr | B13: 35 | C13: 3
A14: Commander Oswal VN | B14: 35 | C14: 3
A15: Divya Hot C/W Dark Parker R/N | B15: 35 | C15: 3
A16: Divya HOT C/W Dark PARKER TSR | B16: 0 | C16: 3
A17: Divya Hot C/W Dark Parker Tsr | B17: 35 | C17: 3
A18: Divya HOT C/W Dark PARKER V/N | B18: 0 | C18: 3
A19: Divya Hot C/W Dark Parker V/N | B19: 35 | C19: 3
A20: Divya Hot C/W Dark Set U/L | B20: 58 | C20: 1
A21: DIVYA HOT COTTSWOOL DARK | B21: 58 | C21: 2
A22: Divya Hot Cottswool Dark Black H/N | B22: 35 | C22: 3
A23: Divya Hot Cottswool Dark H/N | B23: 35 | C23: 3
... A49: Divya Maestro WARMO WHITE V/N | B49: 35 | C49: 5
A50: DIVYA WARMO BABY SET | B50: 58
A51: Divya Warmo Gents (Sp) R/N | B51: 35 | C51: 5
A52: Divya Warmo Gents (Sp) Tsr | B52: 35 | C52: 5
A53: Divya Warmo Ladies (Sp) Lower | B53: 35 | C53: 5
A54: Divya Warmo Ladies (Sp) RN | B54: 35 | C54: 5
A55: Divya Warmo Ladies Slip F/S (Sp) 3/4 | B55: 35 | C55: 5
A56: Extra | B56: 35
A57: Folding Stool | B57: 35
A58: Gaylord Active Lower 5Pc Box | B58: 35 | C58: 5
A59: Gaylord BERMUDA Printed | B59: 35
A60: Gaylord Excel Joy Ladies Trouser PRINTED | B60: 35
A61: Gaylord Real Oswal Light RN | B61: 35 | C61: 3
A62: Gaylord Real Oswal RN | B62: 35 | C62: 3
A63: Gaylord Real Oswal Tsr | B63: 35 | C63: 3
A64: Gaylord Real Oswal VN | B64: 35 | C64: 3
A65: Gaylord Realoswal Tsr | B65: 35 | C65: 3
...

Sheet Sheet4
A1: id | B1: base_name | C1: category | D1: created_at | E1: base_name_nick | F1: BoxMultiple
A2: 04fc4dec-b1fa-4020-95c1-ba152dbf6260 | B2: MAESTRO Casuals SHORTS N-1 | D2: 2026-01-10 16:24:33.294862+00 | E2: Shorts N-1 Piping | F2: 5 | G2: =CONCATENATE("UPDATE products_base SET ""BoxMultiple""=",F2," where id='",A2,"';") -> UPDATE products_base SET "BoxMultiple"=5 where id='04fc4dec-b1fa-4020-95c1-ba152dbf6260';
A3: 1e6cba55-d383-4ce6-82d2-a809ee3b1bfe | B3: MAESTRO Casuals SHORTS D-11 | D3: 2026-01-10 16:24:33.294862+00 | E3: Shorts D-11 Plain | F3: 5 | G3: =CONCATENATE("UPDATE products_base SET ""BoxMultiple""=",F3," where id='",A3,"';") -> UPDATE products_base SET "BoxMultiple"=5 where id='1e6cba55-d383-4ce6-82d2-a809ee3b1bfe';
A4: 6a30e74c-122d-4af8-b4d6-7b3c6d44d3f1 | B4: MAESTRO Casuals LOWER D-10 | D4: 2026-01-10 16:24:33.294862+00 | E4: Lower D-10 Plain | F4: 5 | G4: =CONCATENATE("UPDATE products_base SET ""BoxMultiple""=",F4," where id='",A4,"';") -> UPDATE products_base SET "BoxMultiple"=5 where id='6a30e74c-122d-4af8-b4d6-7b3c6d44d3f1';
A5: a8ffb435-9673-4323-ad0a-f35c52bdba9c | B5: MAESTRO Casuals LOWER D-1 | D5: 2026-01-10 16:24:33.294862+00 | E5: Lower D-1 Piping | F5: 5 | G5: =CONCATENATE("UPDATE products_base SET ""BoxMultiple""=",F5," where id='",A5,"';") -> UPDATE products_base SET "BoxMultiple"=5 where id='a8ffb435-9673-4323-ad0a-f35c52bdba9c';
A6: 6d9c096a-84b3-490c-8e17-7cf2c0baf7e7 | B6: BED SHEET 1+2 | D6: 2026-01-10 16:24:33.294862+00 | F6: 1 | G6: =CONCATENATE("UPDATE products_base SET ""BoxMultiple""=",F6," where id='",A6,"';") -> UPDATE products_base SET "BoxMultiple"=1 where id='6d9c096a-84b3-490c-8e17-7cf2c0baf7e7';
A7: 21ea9f73-fbaa-434a-a43f-7a4a3be5f9fb | B7: BodyGuard FLAIR Gents SET RNFS+I/E | D7: 2026-01-10 16:24:33.294862+00 | F7: 1 | G7: =CONCATENATE("UPDATE products_base SET ""BoxMultiple""=",F7," where id='",A7,"';") -> UPDATE products_base SET "BoxMultiple"=1 where id='21ea9f73-fbaa-434a-a43f-7a4a3be5f9fb';
A8: 65fc7fe1-14f0-4291-93ea-8a84f5ec85a4 | B8: BodyGuard FLAIR Kids SET RNFS+I/E | D8: 2026-01-10 16:24:33.294862+00 | F8: 1 | G8: =CONCATENATE("UPDATE products_base SET ""BoxMultiple""=",F8," where id='",A8,"';") -> UPDATE products_base SET "BoxMultiple"=1 where id='65fc7fe1-14f0-4291-93ea-8a84f5ec85a4';
A9: cc505735-898e-4ad8-8d77-37d997038605 | B9: BodyGuard FLAIR Ladies SET RNFS 3/4+I/E | D9: 2026-01-10 16:24:33.294862+00 | F9: 1 | G9: =CONCATENATE("UPDATE products_base SET ""BoxMultiple""=",F9," where id='",A9,"';") -> UPDATE products_base SET "BoxMultiple"=1 where id='cc505735-898e-4ad8-8d77-37d997038605';
A10: ceb825d5-d3b2-4b74-919c-e75006fce8ba | B10: COMMANDER OSWAL RN | D10: 2026-01-10 16:24:33.294862+00 | F10: 3 | G10: =CONCATENATE("UPDATE products_base SET ""BoxMultiple""=",F10," where id='",A10,"';") -> UPDATE products_base SET "BoxMultiple"=3 where id='ceb825d5-d3b2-4b74-919c-e75006fce8ba';
A11: 82358935-e086-4a42-8969-af1642a66641 | B11: COMMANDER OSWAL TSR | D11: 2026-01-10 16:24:33.294862+00 | F11: 3 | G11: =CONCATENATE("UPDATE products_base SET ""BoxMultiple""=",F11," where id='",A11,"';") -> UPDATE products_base SET "BoxMultiple"=3 where id='82358935-e086-4a42-8969-af1642a66641';
A12: 03ae5e3b-4df4-4ab9-874d-58c3c4ed85d6 | B12: COMMANDER OSWAL VN | D12: 2026-01-10 16:24:33.294862+00 | F12: 3 | G12: =CONCATENATE("UPDATE products_base SET ""BoxMultiple""=",F12," where id='",A12,"';") -> UPDATE products_base SET "BoxMultiple"=3 where id='03ae5e3b-4df4-4ab9-874d-58c3c4ed85d6';
A13: 8b2db25a-8974-4a3d-85e2-27fd342a880b | B13: Divya HOT C/W Dark PARKER R/N | D13: 2026-01-10 16:24:33.294862+00 | F13: 3 | G13: =CONCATENATE("UPDATE products_base SET ""BoxMultiple""=",F13," where id='",A13,"';") -> UPDATE products_base SET "BoxMultiple"=3 where id='8b2db25a-8974-4a3d-85e2-27fd342a880b';
A14: 68543e72-eb7a-447b-9b38-828e6ee185b7 | B14: Divya HOT C/W Dark PARKER TSR | D14: 2026-01-10 16:24:33.294862+00 | F14: 3 | G14: =CONCATENATE("UPDATE products_base SET ""BoxMultiple""=",F14," where id='",A14,"';") -> UPDATE products_base SET "BoxMultiple"=3 where id='68543e72-eb7a-447b-9b38-828e6ee185b7';
A15: 5243118f-3b36-4c2f-9939-5800099b5893 | B15: Divya HOT C/W Dark PARKER V/N | D15: 2026-01-10 16:24:33.294862+00 | F15: 3 | G15: =CONCATENATE("UPDATE products_base SET ""BoxMultiple""=",F15," where id='",A15,"';") -> UPDATE products_base SET "BoxMultiple"=3 where id='5243118f-3b36-4c2f-9939-5800099b5893';
A16: 648d0ff7-ff8c-46d5-8e7d-da0df09148ae | B16: DIVYA HOT C/W DARK SET U/L | D16: 2026-01-10 16:24:33.294862+00 | F16: 1 | G16: =CONCATENATE("UPDATE products_base SET ""BoxMultiple""=",F16," where id='",A16,"';") -> UPDATE products_base SET "BoxMultiple"=1 where id='648d0ff7-ff8c-46d5-8e7d-da0df09148ae';
A17: 9cc71e71-1c7f-454b-9564-f77bb4c6e4c3 | B17: DIVYA HOT COTTSWOOL DARK BLACK H/N | D17: 2026-01-10 16:24:33.294862+00 | F17: 3 | G17: =CONCATENATE("UPDATE products_base SET ""BoxMultiple""=",F17," where id='",A17,"';") -> UPDATE products_base SET "BoxMultiple"=3 where id='9cc71e71-1c7f-454b-9564-f77bb4c6e4c3';
... A79: c2f5e90d-9bd1-4955-aed2-bed0571facb0 | B79: NEU OSWAL VN | D79: 2026-01-10 16:24:33.294862+00 | F79: 3 | G79: =CONCATENATE("UPDATE products_base SET ""BoxMultiple""=",F79," where id='",A79,"';") -> UPDATE products_base SET "BoxMultiple"=3 where id='c2f5e90d-9bd1-4955-aed2-bed0571facb0';
